2021-06-15 14:07:21.492 [error] <0.4753.0>@base64:encode:45 gen_server <0.4753.0> terminated with reason: no function clause matching base64:encode(nil) line 45
2021-06-15 14:07:21.519 [error] <0.4753.0>@base64:encode:45 CRASH REPORT Process <0.4753.0> with 1 neighbours crashed with reason: no function clause matching base64:encode(nil) line 45
2021-06-15 14:07:21.545 [error] <0.4752.0>@base64:encode:45 Cowboy stream 1 with ranch listener 'Elixir.Api.Router.HTTP' and connection process <0.4751.0> had its request process exit with reason: no function clause matching base64:encode(nil) line 45
2021-06-15 14:10:49.113 [error] <0.4760.0> CRASH REPORT Process <0.4760.0> with 1 neighbours exited with reason: {{{{#{'__exception__' => true,'__struct__' => 'Elixir.UndefinedFunctionError',arity => 0,function => task_create,message => nil,module => nil,reason => nil},[{nil,task_create,[],[]},{'Elixir.Api.TaskEndpoint','-do_match/4-fun-8-',2,[{file,"lib/task_management/task_endpoint.ex"},{line,119}]},{'Elixir.Api.TaskEndpoint',dispatch,2,[{file,"lib/plug/router.ex"},{line,284}]},{'Elixir.Api.TaskEndpoint',plug_builder_call,2,[{file,"lib/task_management/task_endpoint.ex"},{line,1}]},{'Elixir.Plug',forward,...},...]},...},...},...}
2021-06-15 14:10:49.114 [error] <0.4760.0> Cowboy stream 1 with ranch listener 'Elixir.Api.Router.HTTP' and connection process <0.4759.0> had its request process exit with reason: {{{#{'__exception__' => true,'__struct__' => 'Elixir.UndefinedFunctionError',arity => 0,function => task_create,message => nil,module => nil,reason => nil},[{nil,task_create,[],[]},{'Elixir.Api.TaskEndpoint','-do_match/4-fun-8-',2,[{file,"lib/task_management/task_endpoint.ex"},{line,119}]},{'Elixir.Api.TaskEndpoint',dispatch,2,[{file,"lib/plug/router.ex"},{line,284}]},{'Elixir.Api.TaskEndpoint',plug_builder_call,2,[{file,"lib/task_management/task_endpoint.ex"},{line,1}]},{'Elixir.Plug',forward,...},...]},...},...}
2021-06-15 14:19:19.372 [error] <0.404.0>@Elixir.UserManagement.Application:start CRASH REPORT Process <0.404.0> with 0 neighbours exited with reason: call to undefined function 'Elixir.UserManagement.Application':start(normal, []) in application_master:init/4 line 138
2021-06-15 14:21:27.574 [error] <0.391.0>@Elixir.UserManagement.Application:start CRASH REPORT Process <0.391.0> with 0 neighbours exited with reason: call to undefined function 'Elixir.UserManagement.Application':start(normal, []) in application_master:init/4 line 138
2021-06-15 14:29:20.001 [error] <0.391.0>@Elixir.UserManagement.Application:start CRASH REPORT Process <0.391.0> with 0 neighbours exited with reason: call to undefined function 'Elixir.UserManagement.Application':start(normal, []) in application_master:init/4 line 138
2021-06-15 14:52:11.563 [error] <0.416.0>@Elixir.UserManagement.Application:start CRASH REPORT Process <0.416.0> with 0 neighbours exited with reason: call to undefined function 'Elixir.UserManagement.Application':start(normal, []) in application_master:init/4 line 138
2021-06-15 15:28:30.647 [error] <0.526.0>@Elixir.UserManagement.Application:start CRASH REPORT Process <0.526.0> with 0 neighbours exited with reason: call to undefined function 'Elixir.UserManagement.Application':start(normal, []) in application_master:init/4 line 138
2021-06-15 15:29:42.688 [error] <0.411.0>@Elixir.UserManagement.Application:start CRASH REPORT Process <0.411.0> with 0 neighbours exited with reason: call to undefined function 'Elixir.UserManagement.Application':start(normal, []) in application_master:init/4 line 138
2021-06-15 15:33:41.949 [error] <0.529.0> Supervisor {<0.529.0>,ranch_listener_sup} had child ranch_acceptors_sup started with ranch_acceptors_sup:start_link('Elixir.Api.Router.HTTP', ranch_tcp) at undefined exit with reason badarg in context start_error
2021-06-15 15:33:41.949 [error] <0.531.0>@inet_tcp:listen:160 CRASH REPORT Process <0.531.0> with 0 neighbours exited with reason: bad argument in inet_tcp:listen/2 line 160
2021-06-15 15:33:41.949 [error] <0.528.0> Supervisor 'Elixir.TaskManagement.Supervisor' had child {ranch_listener_sup,'Elixir.Api.Router.HTTP'} started with ranch_listener_sup:start_link('Elixir.Api.Router.HTTP', ranch_tcp, #{max_connections => 16384,num_acceptors => 100,socket_opts => [{port,nil}]}, cowboy_clear, #{env => #{dispatch => [{'_',[],[{'_',[],'Elixir.Plug.Cowboy.Handler',{'Elixir.Api.Router',[]}}]}]},...}) at undefined exit with reason {shutdown,{failed_to_start_child,ranch_acceptors_sup,badarg}} in context start_error
2021-06-15 15:33:41.949 [error] <0.526.0> CRASH REPORT Process <0.526.0> with 0 neighbours exited with reason: {{shutdown,{failed_to_start_child,{ranch_listener_sup,'Elixir.Api.Router.HTTP'},{shutdown,{failed_to_start_child,ranch_acceptors_sup,badarg}}}},{'Elixir.TaskManagement.Application',start,[normal,[]]}} in application_master:init/4 line 138
2021-06-15 15:35:02.079 [error] <0.528.0> Supervisor 'Elixir.TaskManagement.Supervisor' had child 'Elixir.Api.Service.Publisher' started with 'Elixir.Api.Service.Publisher':start_link([{app_id,task_management}]) at undefined exit with reason {'EXIT',{badarg,[{erlang,byte_size,[nil],[]},{'Elixir.Api.Service.Publisher',start,2,[{file,"lib/services/publisher.ex"},{line,2}]},{supervisor,do_start_child_i,3,[{file,"supervisor.erl"},{line,385}]},{supervisor,do_start_child,2,[{file,"supervisor.erl"},{line,371}]},{supervisor,'-start_children/2-fun-0-',3,[{file,"supervisor.erl"},{line,355}]},{supervisor,children_map,4,[{file,"supervisor.erl"},{line,1171}]},{supervisor,init_children,2,[{file,"supervisor.erl"},{line,321}]},{gen_server,init_it,...}]}} in context start_error
2021-06-15 15:35:02.080 [error] <0.526.0> CRASH REPORT Process <0.526.0> with 0 neighbours exited with reason: {{shutdown,{failed_to_start_child,'Elixir.Api.Service.Publisher',{'EXIT',{badarg,[{erlang,byte_size,[nil],[]},{'Elixir.Api.Service.Publisher',start,2,[{file,"lib/services/publisher.ex"},{line,2}]},{supervisor,do_start_child_i,3,[{file,"supervisor.erl"},{line,385}]},{supervisor,do_start_child,2,[{file,"supervisor.erl"},{line,371}]},{supervisor,'-start_children/2-fun-0-',3,[{file,"supervisor.erl"},{line,355}]},{supervisor,children_map,4,[{file,"supervisor.erl"},{line,1171}]},{supervisor,init_children,...},...]}}}},...} in application_master:init/4 line 138
2021-06-15 15:39:08.738 [error] <0.528.0> Supervisor 'Elixir.TaskManagement.Supervisor' had child 'Elixir.Api.Service.Publisher' started with 'Elixir.Api.Service.Publisher':start_link([{app_id,task_management}]) at undefined exit with reason {'EXIT',{badarg,[{erlang,byte_size,[nil],[]},{'Elixir.Api.Service.Publisher',start,2,[{file,"lib/services/publisher.ex"},{line,2}]},{supervisor,do_start_child_i,3,[{file,"supervisor.erl"},{line,385}]},{supervisor,do_start_child,2,[{file,"supervisor.erl"},{line,371}]},{supervisor,'-start_children/2-fun-0-',3,[{file,"supervisor.erl"},{line,355}]},{supervisor,children_map,4,[{file,"supervisor.erl"},{line,1171}]},{supervisor,init_children,2,[{file,"supervisor.erl"},{line,321}]},{gen_server,init_it,...}]}} in context start_error
2021-06-15 15:39:08.739 [error] <0.526.0> CRASH REPORT Process <0.526.0> with 0 neighbours exited with reason: {{shutdown,{failed_to_start_child,'Elixir.Api.Service.Publisher',{'EXIT',{badarg,[{erlang,byte_size,[nil],[]},{'Elixir.Api.Service.Publisher',start,2,[{file,"lib/services/publisher.ex"},{line,2}]},{supervisor,do_start_child_i,3,[{file,"supervisor.erl"},{line,385}]},{supervisor,do_start_child,2,[{file,"supervisor.erl"},{line,371}]},{supervisor,'-start_children/2-fun-0-',3,[{file,"supervisor.erl"},{line,355}]},{supervisor,children_map,4,[{file,"supervisor.erl"},{line,1171}]},{supervisor,init_children,...},...]}}}},...} in application_master:init/4 line 138
2021-06-15 15:40:49.248 [error] <0.412.0> Supervisor 'Elixir.TaskManagement.Supervisor' had child 'Elixir.Api.Service.Publisher' started with 'Elixir.Api.Service.Publisher':start_link([{app_id,task_management}]) at undefined exit with reason {'EXIT',{badarg,[{erlang,byte_size,[nil],[]},{'Elixir.Api.Service.Publisher',start,2,[{file,"lib/services/publisher.ex"},{line,2}]},{supervisor,do_start_child_i,3,[{file,"supervisor.erl"},{line,385}]},{supervisor,do_start_child,2,[{file,"supervisor.erl"},{line,371}]},{supervisor,'-start_children/2-fun-0-',3,[{file,"supervisor.erl"},{line,355}]},{supervisor,children_map,4,[{file,"supervisor.erl"},{line,1171}]},{supervisor,init_children,2,[{file,"supervisor.erl"},{line,321}]},{gen_server,init_it,...}]}} in context start_error
2021-06-15 15:40:49.248 [error] <0.410.0> CRASH REPORT Process <0.410.0> with 0 neighbours exited with reason: {{shutdown,{failed_to_start_child,'Elixir.Api.Service.Publisher',{'EXIT',{badarg,[{erlang,byte_size,[nil],[]},{'Elixir.Api.Service.Publisher',start,2,[{file,"lib/services/publisher.ex"},{line,2}]},{supervisor,do_start_child_i,3,[{file,"supervisor.erl"},{line,385}]},{supervisor,do_start_child,2,[{file,"supervisor.erl"},{line,371}]},{supervisor,'-start_children/2-fun-0-',3,[{file,"supervisor.erl"},{line,355}]},{supervisor,children_map,4,[{file,"supervisor.erl"},{line,1171}]},{supervisor,init_children,...},...]}}}},...} in application_master:init/4 line 138
2021-06-15 15:41:21.128 [error] <0.412.0> Supervisor 'Elixir.TaskManagement.Supervisor' had child 'Elixir.Api.Service.Publisher' started with 'Elixir.Api.Service.Publisher':start_link([{app_id,task_management}]) at undefined exit with reason {'EXIT',{badarg,[{erlang,byte_size,[nil],[]},{'Elixir.Api.Service.Publisher',start,2,[{file,"lib/services/publisher.ex"},{line,2}]},{supervisor,do_start_child_i,3,[{file,"supervisor.erl"},{line,385}]},{supervisor,do_start_child,2,[{file,"supervisor.erl"},{line,371}]},{supervisor,'-start_children/2-fun-0-',3,[{file,"supervisor.erl"},{line,355}]},{supervisor,children_map,4,[{file,"supervisor.erl"},{line,1171}]},{supervisor,init_children,2,[{file,"supervisor.erl"},{line,321}]},{gen_server,init_it,...}]}} in context start_error
2021-06-15 15:41:21.128 [error] <0.410.0> CRASH REPORT Process <0.410.0> with 0 neighbours exited with reason: {{shutdown,{failed_to_start_child,'Elixir.Api.Service.Publisher',{'EXIT',{badarg,[{erlang,byte_size,[nil],[]},{'Elixir.Api.Service.Publisher',start,2,[{file,"lib/services/publisher.ex"},{line,2}]},{supervisor,do_start_child_i,3,[{file,"supervisor.erl"},{line,385}]},{supervisor,do_start_child,2,[{file,"supervisor.erl"},{line,371}]},{supervisor,'-start_children/2-fun-0-',3,[{file,"supervisor.erl"},{line,355}]},{supervisor,children_map,4,[{file,"supervisor.erl"},{line,1171}]},{supervisor,init_children,...},...]}}}},...} in application_master:init/4 line 138
2021-06-15 15:42:03.574 [error] <0.412.0> Supervisor 'Elixir.TaskManagement.Supervisor' had child 'Elixir.Api.Service.Publisher' started with 'Elixir.Api.Service.Publisher':start_link([{app_id,task_management}]) at undefined exit with reason {'EXIT',{badarg,[{erlang,byte_size,[nil],[]},{'Elixir.Api.Service.Publisher',start,2,[{file,"lib/services/publisher.ex"},{line,2}]},{supervisor,do_start_child_i,3,[{file,"supervisor.erl"},{line,385}]},{supervisor,do_start_child,2,[{file,"supervisor.erl"},{line,371}]},{supervisor,'-start_children/2-fun-0-',3,[{file,"supervisor.erl"},{line,355}]},{supervisor,children_map,4,[{file,"supervisor.erl"},{line,1171}]},{supervisor,init_children,2,[{file,"supervisor.erl"},{line,321}]},{gen_server,init_it,...}]}} in context start_error
2021-06-15 15:42:03.574 [error] <0.410.0> CRASH REPORT Process <0.410.0> with 0 neighbours exited with reason: {{shutdown,{failed_to_start_child,'Elixir.Api.Service.Publisher',{'EXIT',{badarg,[{erlang,byte_size,[nil],[]},{'Elixir.Api.Service.Publisher',start,2,[{file,"lib/services/publisher.ex"},{line,2}]},{supervisor,do_start_child_i,3,[{file,"supervisor.erl"},{line,385}]},{supervisor,do_start_child,2,[{file,"supervisor.erl"},{line,371}]},{supervisor,'-start_children/2-fun-0-',3,[{file,"supervisor.erl"},{line,355}]},{supervisor,children_map,4,[{file,"supervisor.erl"},{line,1171}]},{supervisor,init_children,...},...]}}}},...} in application_master:init/4 line 138
2021-06-15 15:50:24.995 [error] <0.393.0> Supervisor 'Elixir.TaskManagement.Supervisor' had child 'Elixir.Api.Service.Publisher' started with 'Elixir.Api.Service.Publisher':start_link([{app_id,task_management}]) at undefined exit with reason {'EXIT',{badarg,[{erlang,byte_size,[nil],[]},{'Elixir.Api.Service.Publisher',start,2,[{file,"lib/services/publisher.ex"},{line,2}]},{supervisor,do_start_child_i,3,[{file,"supervisor.erl"},{line,385}]},{supervisor,do_start_child,2,[{file,"supervisor.erl"},{line,371}]},{supervisor,'-start_children/2-fun-0-',3,[{file,"supervisor.erl"},{line,355}]},{supervisor,children_map,4,[{file,"supervisor.erl"},{line,1171}]},{supervisor,init_children,2,[{file,"supervisor.erl"},{line,321}]},{gen_server,init_it,...}]}} in context start_error
2021-06-15 15:50:24.995 [error] <0.391.0> CRASH REPORT Process <0.391.0> with 0 neighbours exited with reason: {{shutdown,{failed_to_start_child,'Elixir.Api.Service.Publisher',{'EXIT',{badarg,[{erlang,byte_size,[nil],[]},{'Elixir.Api.Service.Publisher',start,2,[{file,"lib/services/publisher.ex"},{line,2}]},{supervisor,do_start_child_i,3,[{file,"supervisor.erl"},{line,385}]},{supervisor,do_start_child,2,[{file,"supervisor.erl"},{line,371}]},{supervisor,'-start_children/2-fun-0-',3,[{file,"supervisor.erl"},{line,355}]},{supervisor,children_map,4,[{file,"supervisor.erl"},{line,1171}]},{supervisor,init_children,...},...]}}}},...} in application_master:init/4 line 138
2021-06-15 15:52:01.220 [error] <0.405.0> Supervisor 'Elixir.TaskManagement.Supervisor' had child 'Elixir.Api.Service.Publisher' started with 'Elixir.Api.Service.Publisher':start_link([{app_id,task_management}]) at undefined exit with reason {'EXIT',{badarg,[{erlang,byte_size,[nil],[]},{'Elixir.Api.Service.Publisher',start,2,[{file,"lib/services/publisher.ex"},{line,2}]},{supervisor,do_start_child_i,3,[{file,"supervisor.erl"},{line,385}]},{supervisor,do_start_child,2,[{file,"supervisor.erl"},{line,371}]},{supervisor,'-start_children/2-fun-0-',3,[{file,"supervisor.erl"},{line,355}]},{supervisor,children_map,4,[{file,"supervisor.erl"},{line,1171}]},{supervisor,init_children,2,[{file,"supervisor.erl"},{line,321}]},{gen_server,init_it,...}]}} in context start_error
2021-06-15 15:52:01.220 [error] <0.403.0> CRASH REPORT Process <0.403.0> with 0 neighbours exited with reason: {{shutdown,{failed_to_start_child,'Elixir.Api.Service.Publisher',{'EXIT',{badarg,[{erlang,byte_size,[nil],[]},{'Elixir.Api.Service.Publisher',start,2,[{file,"lib/services/publisher.ex"},{line,2}]},{supervisor,do_start_child_i,3,[{file,"supervisor.erl"},{line,385}]},{supervisor,do_start_child,2,[{file,"supervisor.erl"},{line,371}]},{supervisor,'-start_children/2-fun-0-',3,[{file,"supervisor.erl"},{line,355}]},{supervisor,children_map,4,[{file,"supervisor.erl"},{line,1171}]},{supervisor,init_children,...},...]}}}},...} in application_master:init/4 line 138
2021-06-15 16:00:17.369 [error] <0.412.0> Supervisor 'Elixir.TaskManagement.Supervisor' had child 'Elixir.Api.Service.Publisher' started with 'Elixir.Api.Service.Publisher':start_link([{app_id,task_management}]) at undefined exit with reason {'EXIT',{badarg,[{erlang,byte_size,[nil],[]},{'Elixir.Api.Service.Publisher',start,2,[{file,"lib/services/publisher.ex"},{line,2}]},{supervisor,do_start_child_i,3,[{file,"supervisor.erl"},{line,385}]},{supervisor,do_start_child,2,[{file,"supervisor.erl"},{line,371}]},{supervisor,'-start_children/2-fun-0-',3,[{file,"supervisor.erl"},{line,355}]},{supervisor,children_map,4,[{file,"supervisor.erl"},{line,1171}]},{supervisor,init_children,2,[{file,"supervisor.erl"},{line,321}]},{gen_server,init_it,...}]}} in context start_error
2021-06-15 16:00:17.370 [error] <0.410.0> CRASH REPORT Process <0.410.0> with 0 neighbours exited with reason: {{shutdown,{failed_to_start_child,'Elixir.Api.Service.Publisher',{'EXIT',{badarg,[{erlang,byte_size,[nil],[]},{'Elixir.Api.Service.Publisher',start,2,[{file,"lib/services/publisher.ex"},{line,2}]},{supervisor,do_start_child_i,3,[{file,"supervisor.erl"},{line,385}]},{supervisor,do_start_child,2,[{file,"supervisor.erl"},{line,371}]},{supervisor,'-start_children/2-fun-0-',3,[{file,"supervisor.erl"},{line,355}]},{supervisor,children_map,4,[{file,"supervisor.erl"},{line,1171}]},{supervisor,init_children,...},...]}}}},...} in application_master:init/4 line 138
2021-06-15 16:57:58.655 [error] <0.412.0> Supervisor 'Elixir.TaskManagement.Supervisor' had child 'Elixir.Api.Service.Publisher' started with 'Elixir.Api.Service.Publisher':start_link([{app_id,task_management}]) at undefined exit with reason {'EXIT',{badarg,[{erlang,byte_size,[nil],[]},{'Elixir.Api.Service.Publisher',start,2,[{file,"lib/services/publisher.ex"},{line,2}]},{supervisor,do_start_child_i,3,[{file,"supervisor.erl"},{line,385}]},{supervisor,do_start_child,2,[{file,"supervisor.erl"},{line,371}]},{supervisor,'-start_children/2-fun-0-',3,[{file,"supervisor.erl"},{line,355}]},{supervisor,children_map,4,[{file,"supervisor.erl"},{line,1171}]},{supervisor,init_children,2,[{file,"supervisor.erl"},{line,321}]},{gen_server,init_it,...}]}} in context start_error
2021-06-15 16:57:58.655 [error] <0.410.0> CRASH REPORT Process <0.410.0> with 0 neighbours exited with reason: {{shutdown,{failed_to_start_child,'Elixir.Api.Service.Publisher',{'EXIT',{badarg,[{erlang,byte_size,[nil],[]},{'Elixir.Api.Service.Publisher',start,2,[{file,"lib/services/publisher.ex"},{line,2}]},{supervisor,do_start_child_i,3,[{file,"supervisor.erl"},{line,385}]},{supervisor,do_start_child,2,[{file,"supervisor.erl"},{line,371}]},{supervisor,'-start_children/2-fun-0-',3,[{file,"supervisor.erl"},{line,355}]},{supervisor,children_map,4,[{file,"supervisor.erl"},{line,1171}]},{supervisor,init_children,...},...]}}}},...} in application_master:init/4 line 138
2021-06-15 18:28:53.766 [error] <0.1436.0> Supervisor 'Elixir.TaskManagement.Supervisor' had child 'Elixir.Api.Service.Publisher' started with 'Elixir.Api.Service.Publisher':start_link([{app_id,task_management}]) at undefined exit with reason {'EXIT',{badarg,[{erlang,byte_size,[nil],[]},{'Elixir.Api.Service.Publisher',start,2,[{file,"lib/services/publisher.ex"},{line,2}]},{supervisor,do_start_child_i,3,[{file,"supervisor.erl"},{line,385}]},{supervisor,do_start_child,2,[{file,"supervisor.erl"},{line,371}]},{supervisor,'-start_children/2-fun-0-',3,[{file,"supervisor.erl"},{line,355}]},{supervisor,children_map,4,[{file,"supervisor.erl"},{line,1171}]},{supervisor,init_children,2,[{file,"supervisor.erl"},{line,321}]},{gen_server,init_it,...}]}} in context start_error
2021-06-15 18:28:53.768 [error] <0.1434.0> CRASH REPORT Process <0.1434.0> with 0 neighbours exited with reason: {{shutdown,{failed_to_start_child,'Elixir.Api.Service.Publisher',{'EXIT',{badarg,[{erlang,byte_size,[nil],[]},{'Elixir.Api.Service.Publisher',start,2,[{file,"lib/services/publisher.ex"},{line,2}]},{supervisor,do_start_child_i,3,[{file,"supervisor.erl"},{line,385}]},{supervisor,do_start_child,2,[{file,"supervisor.erl"},{line,371}]},{supervisor,'-start_children/2-fun-0-',3,[{file,"supervisor.erl"},{line,355}]},{supervisor,children_map,4,[{file,"supervisor.erl"},{line,1171}]},{supervisor,init_children,...},...]}}}},...} in application_master:init/4 line 138
2021-06-15 18:36:09.284 [error] <0.411.0> CRASH REPORT Process <0.411.0> with 0 neighbours exited with reason: #{'__exception__' => true,'__struct__' => 'Elixir.ArgumentError',message => <<"The module Api.Service.Publisher was given as a child to a supervisor but it does not exist.">>} in 'Elixir.Supervisor':init_child/1 line 631 in application_master:init/4 line 138
2021-06-15 18:37:40.460 [error] <0.520.0> CRASH REPORT Process <0.520.0> with 0 neighbours exited with reason: #{'__exception__' => true,'__struct__' => 'Elixir.ArgumentError',message => <<"The module Api.Service.Publisher was given as a child to a supervisor but it does not exist.">>} in 'Elixir.Supervisor':init_child/1 line 631 in application_master:init/4 line 138
2021-06-15 18:40:34.078 [error] <0.510.0> CRASH REPORT Process <0.510.0> with 1 neighbours exited with reason: {{{{#{'__exception__' => true,'__struct__' => 'Elixir.CondClauseError'},[{'Elixir.Api.TaskEndpoint','-do_match/4-fun-2-',2,[{file,"lib/task_management/task_endpoint.ex"},{line,52}]},{'Elixir.Api.TaskEndpoint',dispatch,2,[{file,"lib/plug/router.ex"},{line,284}]},{'Elixir.Api.TaskEndpoint',plug_builder_call,2,[{file,"lib/task_management/task_endpoint.ex"},{line,1}]},{'Elixir.Plug',forward,4,[{file,"lib/plug.ex"},{line,168}]},{'Elixir.Api.Router',dispatch,2,[{file,"lib/plug/router.ex"},{line,...}]},...]},...},...},...}
2021-06-15 18:40:34.085 [error] <0.510.0> Cowboy stream 1 with ranch listener 'Elixir.Api.Router.HTTP' and connection process <0.509.0> had its request process exit with reason: {{{#{'__exception__' => true,'__struct__' => 'Elixir.CondClauseError'},[{'Elixir.Api.TaskEndpoint','-do_match/4-fun-2-',2,[{file,"lib/task_management/task_endpoint.ex"},{line,52}]},{'Elixir.Api.TaskEndpoint',dispatch,2,[{file,"lib/plug/router.ex"},{line,284}]},{'Elixir.Api.TaskEndpoint',plug_builder_call,2,[{file,"lib/task_management/task_endpoint.ex"},{line,1}]},{'Elixir.Plug',forward,4,[{file,"lib/plug.ex"},{line,168}]},{'Elixir.Api.Router',dispatch,2,[{file,"lib/plug/router.ex"},{line,284}]},...]},...},...}
2021-06-15 18:41:51.613 [error] <0.529.0> CRASH REPORT Process <0.529.0> with 1 neighbours exited with reason: {{{{#{'__exception__' => true,'__struct__' => 'Elixir.CondClauseError'},[{'Elixir.Api.TaskEndpoint','-do_match/4-fun-2-',2,[{file,"lib/task_management/task_endpoint.ex"},{line,52}]},{'Elixir.Api.TaskEndpoint',dispatch,2,[{file,"lib/plug/router.ex"},{line,284}]},{'Elixir.Api.TaskEndpoint',plug_builder_call,2,[{file,"lib/task_management/task_endpoint.ex"},{line,1}]},{'Elixir.Plug',forward,4,[{file,"lib/plug.ex"},{line,168}]},{'Elixir.Api.Router',dispatch,2,[{file,"lib/plug/router.ex"},{line,...}]},...]},...},...},...}
2021-06-15 18:41:51.622 [error] <0.529.0> Cowboy stream 1 with ranch listener 'Elixir.Api.Router.HTTP' and connection process <0.528.0> had its request process exit with reason: {{{#{'__exception__' => true,'__struct__' => 'Elixir.CondClauseError'},[{'Elixir.Api.TaskEndpoint','-do_match/4-fun-2-',2,[{file,"lib/task_management/task_endpoint.ex"},{line,52}]},{'Elixir.Api.TaskEndpoint',dispatch,2,[{file,"lib/plug/router.ex"},{line,284}]},{'Elixir.Api.TaskEndpoint',plug_builder_call,2,[{file,"lib/task_management/task_endpoint.ex"},{line,1}]},{'Elixir.Plug',forward,4,[{file,"lib/plug.ex"},{line,168}]},{'Elixir.Api.Router',dispatch,2,[{file,"lib/plug/router.ex"},{line,284}]},...]},...},...}
2021-06-15 18:42:30.199 [error] <0.531.0> CRASH REPORT Process <0.531.0> with 1 neighbours exited with reason: {{{{#{'__exception__' => true,'__struct__' => 'Elixir.CondClauseError'},[{'Elixir.Api.TaskEndpoint','-do_match/4-fun-2-',2,[{file,"lib/task_management/task_endpoint.ex"},{line,52}]},{'Elixir.Api.TaskEndpoint',dispatch,2,[{file,"lib/plug/router.ex"},{line,284}]},{'Elixir.Api.TaskEndpoint',plug_builder_call,2,[{file,"lib/task_management/task_endpoint.ex"},{line,1}]},{'Elixir.Plug',forward,4,[{file,"lib/plug.ex"},{line,168}]},{'Elixir.Api.Router',dispatch,2,[{file,"lib/plug/router.ex"},{line,...}]},...]},...},...},...}
2021-06-15 18:42:30.199 [error] <0.531.0> Cowboy stream 2 with ranch listener 'Elixir.Api.Router.HTTP' and connection process <0.528.0> had its request process exit with reason: {{{#{'__exception__' => true,'__struct__' => 'Elixir.CondClauseError'},[{'Elixir.Api.TaskEndpoint','-do_match/4-fun-2-',2,[{file,"lib/task_management/task_endpoint.ex"},{line,52}]},{'Elixir.Api.TaskEndpoint',dispatch,2,[{file,"lib/plug/router.ex"},{line,284}]},{'Elixir.Api.TaskEndpoint',plug_builder_call,2,[{file,"lib/task_management/task_endpoint.ex"},{line,1}]},{'Elixir.Plug',forward,4,[{file,"lib/plug.ex"},{line,168}]},{'Elixir.Api.Router',dispatch,2,[{file,"lib/plug/router.ex"},{line,284}]},...]},...},...}
2021-06-15 18:48:37.728 [error] <0.534.0> CRASH REPORT Process <0.534.0> with 1 neighbours exited with reason: {{{{#{'__exception__' => true,'__struct__' => 'Elixir.UndefinedFunctionError',arity => 0,function => task_create,message => nil,module => nil,reason => nil},[{nil,task_create,[],[]},{'Elixir.Api.TaskEndpoint','-do_match/4-fun-2-',2,[{file,"lib/task_management/task_endpoint.ex"},{line,80}]},{'Elixir.Api.TaskEndpoint',dispatch,2,[{file,"lib/plug/router.ex"},{line,284}]},{'Elixir.Api.TaskEndpoint',plug_builder_call,2,[{file,"lib/task_management/task_endpoint.ex"},{line,1}]},{'Elixir.Plug',forward,...},...]},...},...},...}
2021-06-15 18:48:37.735 [error] <0.534.0> Cowboy stream 1 with ranch listener 'Elixir.Api.Router.HTTP' and connection process <0.533.0> had its request process exit with reason: {{{#{'__exception__' => true,'__struct__' => 'Elixir.UndefinedFunctionError',arity => 0,function => task_create,message => nil,module => nil,reason => nil},[{nil,task_create,[],[]},{'Elixir.Api.TaskEndpoint','-do_match/4-fun-2-',2,[{file,"lib/task_management/task_endpoint.ex"},{line,80}]},{'Elixir.Api.TaskEndpoint',dispatch,2,[{file,"lib/plug/router.ex"},{line,284}]},{'Elixir.Api.TaskEndpoint',plug_builder_call,2,[{file,"lib/task_management/task_endpoint.ex"},{line,1}]},{'Elixir.Plug',forward,...},...]},...},...}
2021-06-15 18:49:09.402 [error] <0.510.0> CRASH REPORT Process <0.510.0> with 1 neighbours exited with reason: {{{{#{'__exception__' => true,'__struct__' => 'Elixir.UndefinedFunctionError',arity => 0,function => task_create,message => nil,module => nil,reason => nil},[{nil,task_create,[],[]},{'Elixir.Api.TaskEndpoint','-do_match/4-fun-2-',2,[{file,"lib/task_management/task_endpoint.ex"},{line,80}]},{'Elixir.Api.TaskEndpoint',dispatch,2,[{file,"lib/plug/router.ex"},{line,284}]},{'Elixir.Api.TaskEndpoint',plug_builder_call,2,[{file,"lib/task_management/task_endpoint.ex"},{line,1}]},{'Elixir.Plug',forward,...},...]},...},...},...}
2021-06-15 18:49:09.409 [error] <0.510.0> Cowboy stream 1 with ranch listener 'Elixir.Api.Router.HTTP' and connection process <0.509.0> had its request process exit with reason: {{{#{'__exception__' => true,'__struct__' => 'Elixir.UndefinedFunctionError',arity => 0,function => task_create,message => nil,module => nil,reason => nil},[{nil,task_create,[],[]},{'Elixir.Api.TaskEndpoint','-do_match/4-fun-2-',2,[{file,"lib/task_management/task_endpoint.ex"},{line,80}]},{'Elixir.Api.TaskEndpoint',dispatch,2,[{file,"lib/plug/router.ex"},{line,284}]},{'Elixir.Api.TaskEndpoint',plug_builder_call,2,[{file,"lib/task_management/task_endpoint.ex"},{line,1}]},{'Elixir.Plug',forward,...},...]},...},...}
2021-06-15 18:50:12.024 [error] <0.513.0> CRASH REPORT Process <0.513.0> with 1 neighbours exited with reason: {{{{#{'__exception__' => true,'__struct__' => 'Elixir.UndefinedFunctionError',arity => 0,function => task_create,message => nil,module => nil,reason => nil},[{nil,task_create,[],[]},{'Elixir.Api.TaskEndpoint','-do_match/4-fun-2-',2,[{file,"lib/task_management/task_endpoint.ex"},{line,80}]},{'Elixir.Api.TaskEndpoint',dispatch,2,[{file,"lib/plug/router.ex"},{line,284}]},{'Elixir.Api.TaskEndpoint',plug_builder_call,2,[{file,"lib/task_management/task_endpoint.ex"},{line,1}]},{'Elixir.Plug',forward,...},...]},...},...},...}
2021-06-15 18:50:12.024 [error] <0.513.0> Cowboy stream 1 with ranch listener 'Elixir.Api.Router.HTTP' and connection process <0.512.0> had its request process exit with reason: {{{#{'__exception__' => true,'__struct__' => 'Elixir.UndefinedFunctionError',arity => 0,function => task_create,message => nil,module => nil,reason => nil},[{nil,task_create,[],[]},{'Elixir.Api.TaskEndpoint','-do_match/4-fun-2-',2,[{file,"lib/task_management/task_endpoint.ex"},{line,80}]},{'Elixir.Api.TaskEndpoint',dispatch,2,[{file,"lib/plug/router.ex"},{line,284}]},{'Elixir.Api.TaskEndpoint',plug_builder_call,2,[{file,"lib/task_management/task_endpoint.ex"},{line,1}]},{'Elixir.Plug',forward,...},...]},...},...}
2021-06-16 15:37:54.939 [error] <0.547.0> CRASH REPORT Process <0.547.0> with 1 neighbours exited with reason: {{{{#{'__exception__' => true,'__struct__' => 'Elixir.ArgumentError',message => <<"argument error">>},[{erlang,apply,[#{accepted_user_id => nil,created_at => 1623847074,date => nil,description => <<"test">>,id => <<"ac2b8fb0-ce9f-11eb-9f04-54e1ad3fd7c7">>,location => <<"cluj">>,owner_id => <<"60c7bc68291e7f406ce75596">>,reward => <<"2">>,updated_at => 1623847074},update,[<<"ac2b8fb0-ce9f-11eb-9f04-54e1ad3fd7c7">>,<<"location">>,<<"mongooo">>]],[]},{'Elixir.Api.TaskEndpoint','-do_match/4-fun-5-',...},...]},...},...},...}
2021-06-16 15:37:54.990 [error] <0.547.0> Cowboy stream 1 with ranch listener 'Elixir.Api.Router.HTTP' and connection process <0.546.0> had its request process exit with reason: {{{#{'__exception__' => true,'__struct__' => 'Elixir.ArgumentError',message => <<"argument error">>},[{erlang,apply,[#{accepted_user_id => nil,created_at => 1623847074,date => nil,description => <<"test">>,id => <<"ac2b8fb0-ce9f-11eb-9f04-54e1ad3fd7c7">>,location => <<"cluj">>,owner_id => <<"60c7bc68291e7f406ce75596">>,reward => <<"2">>,updated_at => 1623847074},update,[<<"ac2b8fb0-ce9f-11eb-9f04-54e1ad3fd7c7">>,<<"location">>,<<"mongooo">>]],[]},{'Elixir.Api.TaskEndpoint','-do_match/4-fun-5-',...},...]},...},...}
2021-06-16 16:04:50.595 [error] <0.415.0> Failed to start Ranch listener 'Elixir.Api.Router.HTTP' in ranch_tcp:listen([{cacerts,'...'},{key,'...'},{cert,'...'},{port,4000}]) for reason eaddrinuse (address already in use)
2021-06-16 16:04:50.607 [error] <0.413.0> Supervisor {<0.413.0>,ranch_listener_sup} had child ranch_acceptors_sup started with ranch_acceptors_sup:start_link('Elixir.Api.Router.HTTP', ranch_tcp) at undefined exit with reason {listen_error,'Elixir.Api.Router.HTTP',eaddrinuse} in context start_error
2021-06-16 16:04:50.607 [error] <0.415.0> CRASH REPORT Process <0.415.0> with 0 neighbours exited with reason: {listen_error,'Elixir.Api.Router.HTTP',eaddrinuse} in ranch_acceptors_sup:listen_error/5 line 66
2021-06-16 16:04:50.608 [error] <0.412.0> Supervisor 'Elixir.TaskManagement.Supervisor' had child {ranch_listener_sup,'Elixir.Api.Router.HTTP'} started with ranch_listener_sup:start_link('Elixir.Api.Router.HTTP', ranch_tcp, #{max_connections => 16384,num_acceptors => 100,socket_opts => [{port,4000}]}, cowboy_clear, #{env => #{dispatch => [{'_',[],[{'_',[],'Elixir.Plug.Cowboy.Handler',{'Elixir.Api.Router',[]}}]}]},...}) at undefined exit with reason {shutdown,{failed_to_start_child,ranch_acceptors_sup,{listen_error,'Elixir.Api.Router.HTTP',eaddrinuse}}} in context start_error
2021-06-16 16:04:50.608 [error] <0.410.0> CRASH REPORT Process <0.410.0> with 0 neighbours exited with reason: {{shutdown,{failed_to_start_child,{ranch_listener_sup,'Elixir.Api.Router.HTTP'},{shutdown,{failed_to_start_child,ranch_acceptors_sup,{listen_error,'Elixir.Api.Router.HTTP',eaddrinuse}}}}},{'Elixir.TaskManagement.Application',start,[normal,[]]}} in application_master:init/4 line 138
2021-06-16 16:37:59.961 [error] <0.541.0> CRASH REPORT Process <0.541.0> with 0 neighbours exited with reason: {{{{#{'__exception__' => true,'__struct__' => 'Elixir.FunctionClauseError',args => nil,arity => 1,clauses => nil,function => find,kind => nil,module => 'Elixir.Api.Models.Task'},[{'Elixir.Api.Models.Task',find,[<<"ac2b8fb0-ce9f-11eb-9f04-54e1ad3fd7c7">>],[{file,"lib/models/task.ex"},{line,7}]},{'Elixir.Api.TaskEndpoint','-do_match/4-fun-2-',2,[{file,"lib/task_management/task_endpoint.ex"},{line,51}]},{'Elixir.Api.TaskEndpoint',dispatch,2,[{file,"lib/plug/router.ex"},{line,284}]},{'Elixir.Api.TaskEndpoint',...},...]},...},...},...}
2021-06-16 16:38:00.063 [error] <0.541.0> Cowboy stream 1 with ranch listener 'Elixir.Api.Router.HTTP' and connection process <0.540.0> had its request process exit with reason: {{{#{'__exception__' => true,'__struct__' => 'Elixir.FunctionClauseError',args => nil,arity => 1,clauses => nil,function => find,kind => nil,module => 'Elixir.Api.Models.Task'},[{'Elixir.Api.Models.Task',find,[<<"ac2b8fb0-ce9f-11eb-9f04-54e1ad3fd7c7">>],[{file,"lib/models/task.ex"},{line,7}]},{'Elixir.Api.TaskEndpoint','-do_match/4-fun-2-',2,[{file,"lib/task_management/task_endpoint.ex"},{line,51}]},{'Elixir.Api.TaskEndpoint',dispatch,2,[{file,"lib/plug/router.ex"},{line,284}]},{'Elixir.Api.TaskEndpoint',...},...]},...},...}
